package July_9th_Exceptions_Task;

/*âœ… Task 4: Nested Try-Catch

ðŸ“˜ Description:
Write a program with a try-catch block inside another try-catch block.
        Example: Outer block for ArithmeticException, inner for ArrayIndexOutOfBoundsException.*/
public class Task_4 {
    //NestedTryCatchExample
        public static void main(String[] args) {
            try {
                System.out.println("Outer try block starts");

                try {
                    System.out.println("Inner try block starts");

                    // This will throw ArithmeticException
                    int result = 10 / 0;

                    System.out.println("Inner try block ends"); // Won't execute

                } catch (ArithmeticException e) {
                    System.out.println("Caught in inner catch: " + e.getMessage());
                }

                // This will throw NullPointerException
                String str = null;
                System.out.println(str.length());

                System.out.println("Outer try block ends"); // Won't execute

            } catch (NullPointerException e) {
                System.out.println("Caught in outer catch: " + e.getMessage());
            }

            System.out.println("Program continues after nested try-catch.");
        }
    }


